Workbook

Sheet Start Here
A1: Media M&A Case Study | Paramount–Warner Bros. Discovery Style
A2: Hypothetical strategic acquisition analysis • USD billions unless stated • Educational portfolio model
A4: IMPORTANT CASE SCOPE
A5: Case type | B5: A fictional, illustrative media-industry M&A analysis inspired by strategic themes in a Paramount / Warner Bros. Discovery combination.
A6: Not a real deal model | B6: This workbook does not represent actual offer terms, actual company forecasts, actual debt balances, current share prices, or a verified transaction. All numbers are hypothetical placeholders created for learning.
A7: Strategic question | B7: Could a hypothetical combination of a global studio, streaming service, broadcast networks and content library create value after considering leverage, integration costs, synergies and regulatory risk?
A8: Model tabs | B8: Assumptions → Historical → Projections → DCF → Comps → Transaction → Accretion-Dilution → Sensitivity. → Change Log (review of fixes and open items).
A9: Core outputs | B9: Stand-alone DCF, trading-comps cross-check, illustrative purchase price, sources & uses, synergy bridge, EPS accretion/dilution, leverage and sensitivities.
A10: Units | B10: USD billions except per-share values, share counts in billions, and valuation multiples.
A11: Color convention | B11: Yellow cells are editable assumptions. Formula cells calculate outputs. Change assumptions in the Assumptions sheet and review downstream tabs.
A12: Research discipline | B12: For a real Paramount/WBD analysis, replace every placeholder with source-cited filings, earnings releases, debt schedules, share counts and market prices as of a stated date.
A13: Model limitations | B13: Simplified cash flow, debt, tax, share issuance, purchase accounting, content amortization, restructuring, integration costs, tax attributes and regulatory treatment.
A14: Suggested portfolio claim | B14: Built a hypothetical media-sector M&A model integrating DCF, trading comparables, financing, synergies, leverage, EPS accretion/dilution and scenario analysis. All financial assumptions were illustrative.
A17: M&A CONCEPTS
A18: Enterprise value | B18: Value of the operating business to debt and equity holders; commonly equity value + debt − cash.
A19: DCF | B19: Present value of future free cash flow plus present value of terminal value.
A20: WACC | B20: Weighted average cost of capital, the discount rate for unlevered free cash flow.
A21: Synergies | B21: Incremental benefits from combining companies, net of integration costs and execution risk.
A22: Sources & uses | B22: Funding sources must equal purchase price, refinancing, fees and other transaction uses.
A23: EPS accretion/dilution | B23: Compares pro forma earnings per share with the acquirer’s standalone EPS.
A24: Regulatory risk | B24: Antitrust, media ownership, content licensing and public-interest reviews can delay, reshape or block a deal.

Sheet Public Deal Facts
A1: Public Deal Facts | Paramount–Warner Bros. Discovery
A2: Verified public transaction context as of 27-Oct-2026. This fact sheet is separate from the fictional model assumptions.
A4: Item | B4: Publicly reported information / source
A5: Transaction status | B5: Paramount Skydance announced that it completed the acquisition of Warner Bros. Discovery on 6 October 2026. WBD common stock ceased trading following closing. Source: Paramount official release: https://ir.paramount.com/news-releases/news-release-details/paramount-completes-acquisition-warner-bros-discovery-creating
A6: Cash consideration per WBD share | B6: The official closing release states WBD shareholders received $31.01666668 per share in cash. Source: https://ir.paramount.com/news-releases/news-release-details/paramount-completes-acquisition-warner-bros-discovery-creating
A7: Reported deal value | B7: CBS News described the completed transaction as a $110 billion acquisition. This is a reported headline transaction value, not an input automatically used by this model. Source: https://www.cbsnews.com/news/paramount-warner-bros-discovery-deal-skydance/
A8: Run-rate synergies — management target | B8: The closing release states the company is targeting at least $6 billion in run-rate synergies within three years. This is a forward-looking management target, not an achieved result. Source: https://ir.paramount.com/news-releases/news-release-details/paramount-completes-acquisition-warner-bros-discovery-creating
A9: Free cash flow — management target | B9: The same release states the company expects more than $10 billion in free cash flow by 2030. This is a forward-looking expectation, not a guaranteed outcome. Source: https://ir.paramount.com/news-releases/news-release-details/paramount-completes-acquisition-warner-bros-discovery-creating
A10: Net leverage target | B10: The company said it aims to reduce net leverage to 3.0x by the end of 2029. This is a target, not an achieved leverage ratio. Source: https://ir.paramount.com/news-releases/news-release-details/paramount-completes-acquisition-warner-bros-discovery-creating
A11: Strategic assets combined | B11: The company release describes the combination as bringing together two major film studios, two global streaming services, CBS, HBO, cable networks, CBS News, CNN, sports assets and a large content library. Source: https://ir.paramount.com/news-releases/news-release-details/paramount-completes-acquisition-warner-bros-discovery-creating
A12: Regulatory context | B12: The UK Competition and Markets Authority's case page states the inquiry closed on 17 August 2026 and that the CMA cleared the anticipated acquisition on 6 August 2026. Source: https://www.gov.uk/cma-cases/paramount-slash-warner-bros-discovery-merger-inquiry
A13: Model separation | B13: The Assumptions, Historical, Projections, DCF, Comps and Transaction sheets continue to use fictional educational inputs. Do not present those numbers as the actual deal, company results or the deal's actual financing structure.
A14: How to upgrade to a sourced real-company model | B14: For a true historical deal analysis, collect actual filings and transaction documents for a fixed date: merger agreement, proxy/registration statements, debt tender/exchange documents, company filings, earnings releases, market prices, diluted shares and debt/cash balances. Cite each input and distinguish reported facts from analyst estimates.
A15: Model vs reported: equity value | B15: ="Model offer equity purchase price: $"&TEXT(Transaction!B7,"0.0")&"bn vs ~$81bn reported equity value (announcement of 27-Feb-2026). The model equity is a thin residual and is not comparable. Source: https://www.wlrk.com/transaction/warner-bros-discovery-in-its-110-billion-acquisition-by-paramount/" -> Model offer equity purchase price: $2.4bn vs ~$81bn reported equity value (announcement of 27-Feb-2026). The model equity is a thin residual and is not comparable. Source: https://www.wlrk.com/transaction/warner-bros-discovery-in-its-110-billion-acquisition-by-paramount/
A16: Model vs reported: enterprise value | B16: ="Model implied transaction EV: $"&TEXT(Transaction!B12,"0.0")&"bn vs ~$110bn reported enterprise value. Source: https://www.clearygottlieb.com/news-and-insights/news-listing/paramount-skydances-110-billion-acquisition-of-warner-bros-discovery" -> Model implied transaction EV: $44.4bn vs ~$110bn reported enterprise value. Source: https://www.clearygottlieb.com/news-and-insights/news-listing/paramount-skydances-110-billion-acquisition-of-warner-bros-discovery
A17: Model vs reported: target net debt | B17: ="Model target net debt: $"&TEXT(Historical!D28,"0.0")&"bn vs ~$29bn implied by reported EV less equity ($110bn - $81bn). The fictional $42bn is well above this." -> Model target net debt: $42.0bn vs ~$29bn implied by reported EV less equity ($110bn - $81bn). The fictional $42bn is well above this.

Sheet Assumptions
A1: Editable Assumptions
A2: All inputs are hypothetical USD billions or percentages. These are not Paramount or WBD reported figures.
A4: OPERATING / VALUATION ASSUMPTIONS
A5: Revenue growth Y1 | B5: 0.02 | C5: Illustrative combined revenue growth in first forecast year
A6: Revenue growth Y2 | B6: 0.025 | C6: Illustrative revenue growth
A7: Revenue growth Y3 | B7: 0.03 | C7: Illustrative revenue growth
A8: Revenue growth Y4 | B8: 0.03 | C8: Illustrative revenue growth
A9: Revenue growth Y5 | B9: 0.03 | C9: Illustrative revenue growth
A10: EBITDA margin Y1 | B10: 0.125 | C10: Anchored to 2025A combined margin of ~12.3% ($8.1bn / $66bn); +0.5pt per year thereafter. Excludes synergies (modelled separately). Revised from 16%-20%.
A11: EBITDA margin Y2 | B11: 0.13 | C11: Illustrative adjusted EBITDA margin; +0.5pt/yr recovery vs 2025A (revised)
A12: EBITDA margin Y3 | B12: 0.135 | C12: Illustrative adjusted EBITDA margin; +0.5pt/yr recovery vs 2025A (revised)
A13: EBITDA margin Y4 | B13: 0.14 | C13: Illustrative adjusted EBITDA margin; +0.5pt/yr recovery vs 2025A (revised)
A14: EBITDA margin Y5 | B14: 0.145 | C14: Illustrative adjusted EBITDA margin; +0.5pt/yr recovery vs 2025A (revised)
A15: D&A % revenue | B15: 0.07 | C15: Content amortization and depreciation simplified as % of revenue
A16: Capex % revenue | B16: 0.04 | C16: Capital expenditure assumption
... A28: Refinanced target debt | B28: 14 | C28: Hypothetical debt to refinance at closing
A29: Existing target debt retained | B29: =Historical!D28-B28 -> 28 | C29: Formula: target 2025A net debt less refinanced amount, so all target debt is accounted for (was hard-coded 0, which dropped $28bn of debt)
A30: Acquisition debt funding % total uses | B30: 0.55 | C30: Fraction of transaction uses funded with new debt
A31: Acquirer standalone net income | B31: =Historical!D13 -> -0.4 | C31: Linked to 2025A net income (loss) so it ties to Historical; overwrite with a sourced forward estimate if desired
A32: Acquirer diluted shares | B32: 0.7 | C32: Illustrative buyer diluted shares in billions
A33: Target standalone net income | B33: =Historical!D27 -> -1 | C33: Linked to 2025A net income (loss) so it ties to Historical; overwrite with a sourced forward estimate if desired
A34: Annual run-rate cost synergies | B34: 1.5 | C34: Illustrative annual pre-tax cost synergies; not actual guidance
A35: Year 1 synergy realization | B35: 0.35 | C35: Share of run-rate synergies realized in Year 1
A36: One-time integration costs | B36: 1 | C36: Illustrative pre-tax integration costs in Year 1
A37: Content / restructuring dis-synergies | B37: 0.25 | C37: Illustrative annual pre-tax dis-synergies or stranded costs
A38: Buyer share price | B38: 15 | C38: Illustrative USD per-share price for stock consideration analysis
A39: Stock consideration % | B39: 0.25 | C39: Illustrative share of equity purchase consideration paid in stock
A40: Terminal D&A as % of capex | B40: 1 | C40: Normalizes terminal year so D&A = capex (steady state). Added to fix terminal-value tax shield.
A43: CASE LABELS
A44: Acquirer | B44: Paramount-style MediaCo | C44: Fictional stand-in for a diversified media acquirer
A45: Target | B45: Warner-style Studios & StreamingCo | C45: Fictional stand-in for a studio, streaming and content-library company
A46: Valuation date | B46: Illustrative 31-Dec-2025 | C46: Not a statement about any actual transaction
A47: Currency | B47: USD billions | C47: Per-share metrics in USD

Sheet Historical
A1: Illustrative Standalone Financials
A2: Fictionalized case inputs for two media businesses; not actual reported company data.
A4: ACQUIRER: PARAMOUNT-STYLE MEDIACO
B5: 2023 | C5: 2024 | D5: 2025
A6: Revenue | B6: 30 | C6: 29 | D6: 28
A7: Adjusted EBITDA | B7: 3 | C7: 2.8 | D7: 2.6
A8: D&A / content amortization | B8: -2 | C8: -2.1 | D8: -2.2
A9: EBIT | B9: 1 | C9: 0.7 | D9: 0.4
A10: Interest expense | B10: -0.7 | C10: -0.75 | D10: -0.8
A11: Pre-tax income | B11: 0.3 | C11: -0.05 | D11: -0.4
A12: Cash taxes | B12: -0.1 | C12: 0 | D12: 0
A13: Net income | B13: 0.2 | C13: -0.05 | D13: -0.4
A14: Net debt | B14: 14 | C14: 14.5 | D14: 15
A15: Diluted shares (bn) | B15: 0.67 | C15: 0.68 | D15: 0.7
A18: TARGET: WARNER-STYLE STUDIOS & STREAMINGCO
B19: 2023 | C19: 2024 | D19: 2025
A20: Revenue | B20: 41 | C20: 39 | D20: 38
A21: Adjusted EBITDA | B21: 7 | C21: 6 | D21: 5.5
A22: D&A / content amortization | B22: -4 | C22: -4.2 | D22: -4.3
A23: EBIT | B23: 3 | C23: 1.8 | D23: 1.2
A24: Interest expense | B24: -2 | C24: -2.1 | D24: -2.2
A25: Pre-tax income | B25: 1 | C25: -0.3 | D25: -1
A26: Cash taxes | B26: -0.2 | C26: 0 | D26: 0
A27: Net income | B27: 0.8 | C27: -0.3 | D27: -1
A28: Net debt | B28: 40 | C28: 41 | D28: 42
A29: Diluted shares (bn) | B29: 2.5 | C29: 2.5 | D29: 2.5
A32: All figures in this sheet are invented for the educational scenario. Negative net income is deliberately included to show why P/E may be inappropriate for loss-making media businesses.

Sheet Projections
A1: Combined Company Forecast
A2: Simplified combined operating projections; USD billions. Content amortization treated as D&A.
B4: 2026 | C4: 2027 | D4: 2028 | E4: 2029 | F4: 2030
A5: COMBINED INCOME STATEMENT
A6: Revenue | B6: =(Historical!D6+Historical!D20)*(1+Assumptions!$B$5) -> 67.32 | C6: =B6*(1+Assumptions!$B$6) -> 69.003 | D6: =C6*(1+Assumptions!$B$7) -> 71.07309 | E6: =D6*(1+Assumptions!$B$8) -> 73.205283 | F6: =E6*(1+Assumptions!$B$9) -> 75.401441
A7: Revenue growth | B7: =B6/(Historical!D6+Historical!D20)-1 -> 0.02 | C7: =C6/B6-1 -> 0.025 | D7: =D6/C6-1 -> 0.03 | E7: =E6/D6-1 -> 0.03 | F7: =F6/E6-1 -> 0.03
A8: EBITDA | B8: =B6*Assumptions!$B$10 -> 8.415 | C8: =C6*Assumptions!$B$11 -> 8.97039 | D8: =D6*Assumptions!$B$12 -> 9.5948672 | E8: =E6*Assumptions!$B$13 -> 10.24874 | F8: =F6*Assumptions!$B$14 -> 10.933209
A9: EBITDA margin | B9: =B8/B6 -> 0.125 | C9: =C8/C6 -> 0.13 | D9: =D8/D6 -> 0.135 | E9: =E8/E6 -> 0.14 | F9: =F8/F6 -> 0.145
A10: D&A / content amortization | B10: =-B6*Assumptions!$B$15 -> -4.7124 | C10: =-C6*Assumptions!$B$15 -> -4.83021 | D10: =-D6*Assumptions!$B$15 -> -4.9751163 | E10: =-E6*Assumptions!$B$15 -> -5.1243698 | F10: =-F6*Assumptions!$B$15 -> -5.2781009
A11: EBIT | B11: =B8+B10 -> 3.7026 | C11: =C8+C10 -> 4.14018 | D11: =D8+D10 -> 4.6197508 | E11: =E8+E10 -> 5.1243698 | F11: =F8+F10 -> 5.6551081
A12: Cash taxes on EBIT | B12: =-MAX(0,B11)*Assumptions!$B$17 -> -0.92565 | C12: =-MAX(0,C11)*Assumptions!$B$17 -> -1.035045 | D12: =-MAX(0,D11)*Assumptions!$B$17 -> -1.1549377 | E12: =-MAX(0,E11)*Assumptions!$B$17 -> -1.2810924 | F12: =-MAX(0,F11)*Assumptions!$B$17 -> -1.413777
A13: NOPAT | B13: =B11+B12 -> 2.77695 | C13: =C11+C12 -> 3.105135 | D13: =D11+D12 -> 3.4648131 | E13: =E11+E12 -> 3.8432773 | F13: =F11+F12 -> 4.2413311
A14: D&A add-back | B14: =-B10 -> 4.7124 | C14: =-C10 -> 4.83021 | D14: =-D10 -> 4.9751163 | E14: =-E10 -> 5.1243698 | F14: =-F10 -> 5.2781009
A15: Capex | B15: =-B6*Assumptions!$B$16 -> -2.6928 | C15: =-C6*Assumptions!$B$16 -> -2.76012 | D15: =-D6*Assumptions!$B$16 -> -2.8429236 | E15: =-E6*Assumptions!$B$16 -> -2.9282113 | F15: =-F6*Assumptions!$B$16 -> -3.0160576
A16: Change in NWC | B16: =-(B6-(Historical!D6+Historical!D20))*Assumptions!$B$18 -> -0.0264 | C16: =-(C6-B6)*Assumptions!$B$18 -> -0.03366 | D16: =-(D6-C6)*Assumptions!$B$18 -> -0.0414018 | E16: =-(E6-D6)*Assumptions!$B$18 -> -0.042643854 | F16: =-(F6-E6)*Assumptions!$B$18 -> -0.04392317
A17: Unlevered FCFF | B17: =B13+B14+B15+B16 -> 4.77015 | C17: =C13+C14+C15+C16 -> 5.141565 | D17: =D13+D14+D15+D16 -> 5.555604 | E17: =E13+E14+E15+E16 -> 5.996792 | F17: =F13+F14+F15+F16 -> 6.4594511
A20: SYNERGY BRIDGE (ILLUSTRATIVE)
A21: Run-rate cost synergies | B21: =Assumptions!$B$34 -> 1.5 | C21: =Assumptions!$B$34 -> 1.5 | D21: =Assumptions!$B$34 -> 1.5 | E21: =Assumptions!$B$34 -> 1.5 | F21: =Assumptions!$B$34 -> 1.5
A22: Year 1 realization % | B22: =Assumptions!$B$35 -> 0.35 | C22: =100% -> 1 | D22: =100% -> 1 | E22: =100% -> 1 | F22: =100% -> 1
A23: Year 1 gross synergies | B23: =B21*B22 -> 0.525 | C23: =C21*C22 -> 1.5 | D23: =D21*D22 -> 1.5 | E23: =E21*E22 -> 1.5 | F23: =F21*F22 -> 1.5
A24: Annual dis-synergies / stranded costs | B24: =-Assumptions!$B$37 -> -0.25 | C24: =-Assumptions!$B$37 -> -0.25 | D24: =-Assumptions!$B$37 -> -0.25 | E24: =-Assumptions!$B$37 -> -0.25 | F24: =-Assumptions!$B$37 -> -0.25
A25: Year 1 integration costs | B25: =-Assumptions!$B$36 -> -1 | C25: =0 -> 0 | D25: =0 -> 0 | E25: =0 -> 0 | F25: =0 -> 0
A26: Year 1 net pre-tax deal benefits | B26: =B23+B24+B25 -> -0.725 | C26: =C23+C24+C25 -> 1.25 | D26: =D23+D24+D25 -> 1.25 | E26: =E23+E24+E25 -> 1.25 | F26: =F23+F24+F25 -> 1.25

Sheet DCF
A1: DCF Valuation
A2: Unlevered DCF of hypothetical combined operating business; USD billions.
B4: 2026 | C4: 2027 | D4: 2028 | E4: 2029 | F4: 2030
A5: EBIT | B5: =Projections!B11 -> 3.7026 | C5: =Projections!C11 -> 4.14018 | D5: =Projections!D11 -> 4.6197508 | E5: =Projections!E11 -> 5.1243698 | F5: =Projections!F11 -> 5.6551081
A6: Cash tax rate | B6: =Assumptions!$B$17 -> 0.25 | C6: =Assumptions!$B$17 -> 0.25 | D6: =Assumptions!$B$17 -> 0.25 | E6: =Assumptions!$B$17 -> 0.25 | F6: =Assumptions!$B$17 -> 0.25
A7: NOPAT | B7: =B5*(1-B6) -> 2.77695 | C7: =C5*(1-C6) -> 3.105135 | D7: =D5*(1-D6) -> 3.4648131 | E7: =E5*(1-E6) -> 3.8432773 | F7: =F5*(1-F6) -> 4.2413311
A8: D&A add-back | B8: =Projections!B14 -> 4.7124 | C8: =Projections!C14 -> 4.83021 | D8: =Projections!D14 -> 4.9751163 | E8: =Projections!E14 -> 5.1243698 | F8: =Projections!F14 -> 5.2781009
A9: Capex | B9: =-Projections!B15 -> 2.6928 | C9: =-Projections!C15 -> 2.76012 | D9: =-Projections!D15 -> 2.8429236 | E9: =-Projections!E15 -> 2.9282113 | F9: =-Projections!F15 -> 3.0160576
A10: Change in NWC | B10: =Projections!B16 -> -0.0264 | C10: =Projections!C16 -> -0.03366 | D10: =Projections!D16 -> -0.0414018 | E10: =Projections!E16 -> -0.042643854 | F10: =Projections!F16 -> -0.04392317
A11: Unlevered FCFF | B11: =B7+B8-B9+B10 -> 4.77015 | C11: =C7+C8-C9+C10 -> 5.141565 | D11: =D7+D8-D9+D10 -> 5.555604 | E11: =E7+E8-E9+E10 -> 5.996792 | F11: =F7+F8-F9+F10 -> 6.4594511
A12: Discount period | B12: 1 | C12: 2 | D12: 3 | E12: 4 | F12: 5
A13: Discount factor | B13: =1/(1+$B$20)^B12 -> 0.91648528 | C13: =1/(1+$B$20)^C12 -> 0.83994527 | D13: =1/(1+$B$20)^D12 -> 0.76979747 | E13: =1/(1+$B$20)^E12 -> 0.70550805 | F13: =1/(1+$B$20)^F12 -> 0.64658774
A14: PV of FCFF | B14: =B11*B13 -> 4.3717723 | C14: =C11*C13 -> 4.3186332 | D14: =D11*D13 -> 4.2766899 | E14: =E11*E13 -> 4.230785 | F14: =F11*F13 -> 4.1766019
A17: WACC AND VALUATION SUMMARY
A18: Risk-free rate | B18: =Assumptions!$B$19 -> 0.042
A19: Equity risk premium | B19: =Assumptions!$B$20 -> 0.055
A20: WACC | B20: =B24*B22+B25*B21*(1-B26) -> 0.091125
A21: Pre-tax cost of debt | B21: =Assumptions!$B$22 -> 0.065
A22: Cost of equity (CAPM) | B22: =B18+Assumptions!$B$21*B19 -> 0.10525
A23: Levered beta | B23: =Assumptions!$B$21 -> 1.15
A24: Equity weight | B24: =1-Assumptions!$B$23 -> 0.75
A25: Debt weight | B25: =Assumptions!$B$23 -> 0.25
A26: Cash tax rate | B26: =Assumptions!$B$17 -> 0.25
A27: Perpetual growth | B27: =Assumptions!$B$24 -> 0.025
A28: Terminal year FCFF (normalized, grown) | B28: =B43*(1+B27) -> 6.0412888
A29: Terminal value | B29: =B28/(B20-B27) -> 91.361646
A30: PV terminal value | B30: =B29*F13 -> 59.07332
A31: PV forecast FCFF | B31: =SUM(B14:F14) -> 21.374482
A32: DCF enterprise value | B32: =B30+B31 -> 80.447803
A33: Combined net debt (2025A, pre-deal) | B33: =Historical!D14+Historical!D28 -> 57
A34: DCF equity value (simplified) | B34: =B32-B33 -> 23.447803
A36: WACC = equity weight × cost of equity + debt weight × pre-tax cost of debt × (1 − tax rate). Terminal growth must be below WACC. Enterprise value is before transaction financing and does not equal equity value. Terminal FCFF is normalized so D&A = capex (Assumptions B40). DCF is stand-alone: synergies are excluded.
A38: TERMINAL-YEAR NORMALIZATION
A39: Terminal-year EBITDA | B39: =Projections!F8 -> 10.933209
A40: Normalized terminal D&A (= capex x ratio) | B40: =F9*Assumptions!$B$40 -> 3.0160576
A41: Terminal EBIT | B41: =B39-B40 -> 7.9171513
A42: Terminal NOPAT | B42: =B41*(1-Assumptions!$B$17) -> 5.9378635
A43: Normalized terminal FCFF (before growth) | B43: =B42+B40-F9+F10 -> 5.8939403
A45: DCF vs COMPS CROSS-CHECK
A46: DCF enterprise value | B46: =B32 -> 80.447803
...

Sheet Comps
A1: Trading Comparables Cross-Check
A2: Illustrative fictional media peer set and multiples; not real market data.
A4: FICTIONAL COMPARABLES
A5: Peer | B5: EV / EBITDA | C5: Revenue | D5: EBITDA | E5: Net debt
A6: Fictional Media Peer A | B6: 7 | C6: 25 | D6: 4 | E6: 8
A7: Fictional Media Peer B | B7: 8 | C7: 42 | D7: 7 | E7: 18
A8: Fictional Media Peer C | B8: 9 | C8: 55 | D8: 9 | E8: 24
A9: Fictional Media Peer D | B9: 7.5 | C9: 32 | D9: 5 | E9: 10
A10: Fictional Media Peer E | B10: 8.5 | C10: 48 | D10: 8 | E10: 20
A13: TARGET IMPLIED VALUATION
A14: Median EV / EBITDA | B14: =MEDIAN(B6:B10) -> 8
A15: Target standalone 2025 EBITDA | B15: =Historical!D21 -> 5.5
A16: Target implied enterprise value | B16: =B14*B15 -> 44
A17: Less target net debt | B17: =Historical!D28 -> 42
A18: Target implied equity value | B18: =B16-B17 -> 2
A19: Combined 2025 EBITDA | B19: =Historical!D7+Historical!D21 -> 8.1
A20: Illustrative combined EV at median multiple | B20: =B14*B19 -> 64.8
A22: Comparable analysis is a cross-check only. Real peers must be selected based on business mix, growth, margins, content ownership, leverage and market date.
A24: TARGET EQUITY SENSITIVITY TO MULTIPLE (equity is a thin residual of EV less net debt)
A25: EV / EBITDA | B25: Implied EV | C25: Implied equity | D25: % change vs base
A26: =$B$14+(-1) -> 7 | B26: =A26*$B$15 -> 38.5 | C26: =B26-$B$17 -> -3.5 | D26: =IF($C$28>0,C26/$C$28-1,"n.m.") -> -2.75
A27: =$B$14+(-0.5) -> 7.5 | B27: =A27*$B$15 -> 41.25 | C27: =B27-$B$17 -> -0.75 | D27: =IF($C$28>0,C27/$C$28-1,"n.m.") -> -1.375
A28: =$B$14+(0) -> 8 | B28: =A28*$B$15 -> 44 | C28: =B28-$B$17 -> 2 | D28: =IF($C$28>0,C28/$C$28-1,"n.m.") -> 0
A29: =$B$14+(0.5) -> 8.5 | B29: =A29*$B$15 -> 46.75 | C29: =B29-$B$17 -> 4.75 | D29: =IF($C$28>0,C29/$C$28-1,"n.m.") -> 1.375
A30: =$B$14+(1) -> 9 | B30: =A30*$B$15 -> 49.5 | C30: =B30-$B$17 -> 7.5 | D30: =IF($C$28>0,C30/$C$28-1,"n.m.") -> 2.75
A31: At 7.0x the implied target equity is negative: a 1.0x move changes equity by $5.5bn against a ~$2bn base. Treat the Transaction offer price as illustrative only.

Sheet Transaction
A1: Transaction Structure, Sources & Uses
A2: Simplified hypothetical stock/cash acquisition. USD billions except multiples.
A4: OFFER VALUATION
A5: Target unaffected equity value (comps proxy) | B5: =Comps!B18 -> 2 | E5: Equity value implied by fictional EV/EBITDA peer multiple
A6: Acquisition premium | B6: =Assumptions!$B$26 -> 0.2 | E6: Illustrative premium
A7: Offer equity purchase price | B7: =B5*(1+B6) -> 2.4 | E7: Equity purchase consideration
A8: Target debt refinanced | B8: =Assumptions!$B$28 -> 14 | E8: Hypothetical debt refinance at close
A9: Target debt retained | B9: =Assumptions!$B$29 -> 28 | E9: Assumed debt remaining after close
A10: Transaction fees | B10: =B7*Assumptions!$B$27 -> 0.036 | E10: Fees as % of equity purchase price
A11: Total uses | B11: =SUM(B7:B10)-B9 -> 16.436 | E11: Purchase price + refinanced debt + fees; retained debt excluded from cash uses
A12: Implied transaction enterprise value | B12: =B7+B8+B9 -> 44.4 | E12: Equity purchase price plus debt assumed/refinanced
A15: SOURCES & USES
A16: USES | B16: Amount | C16: SOURCES | D16: Amount | E16: Notes
A17: Equity purchase price | B17: =B7 -> 2.4 | C17: New acquisition debt | D17: =B20*Assumptions!$B$30 -> 9.0398
A18: Debt refinancing | B18: =B8 -> 14 | C18: Stock consideration | D18: =B7*Assumptions!$B$39 -> 0.6
A19: Transaction fees | B19: =B10 -> 0.036 | C19: Buyer cash / other equity funding | D19: =B20-D17-D18 -> 6.7962
A20: Total uses | B20: =SUM(B17:B19) -> 16.436 | C20: Total sources | D20: =SUM(D17:D19) -> 16.436
A22: Sources less uses | B22: =D20-B20 -> 0 | E22: Should equal zero.
A24: New acquisition debt | B24: =D17 -> 9.0398
A25: Stock shares issued (bn) | B25: =D18/Assumptions!$B$38 -> 0.04 | E25: Stock consideration (USD bn) divided by buyer share price (USD/share) = new shares (bn).
A26: Check: refinanced + retained debt less target net debt | B26: =B8+B9-Comps!B17 -> 0
A28: Important: a real transaction sources & uses would separately show cash on balance sheet, refinancing or repayment of all debt, fees, minimum cash, rollover equity, debt-like items, and any share consideration using fully diluted shares and a defined offer price.

Sheet Accretion-Dilution
A1: EPS Accretion / Dilution
A2: Simplified year-one pro forma EPS analysis; USD billions and shares in billions.
A4: PRO FORMA EPS BRIDGE
A5: Acquirer standalone net income | B5: =Assumptions!$B$31 -> -0.4 | C5: Illustrative net income
A6: Acquirer diluted shares | B6: =Assumptions!$B$32 -> 0.7 | C6: Illustrative diluted shares
A7: Acquirer standalone EPS | B7: =B5/B6 -> -0.57142857 | C7: Standalone EPS
A8: Target standalone net income | B8: =Assumptions!$B$33 -> -1 | C8: Illustrative target net income; not historical fact
A9: Year 1 gross synergies | B9: =Assumptions!$B$34*Assumptions!$B$35 -> 0.525 | C9: Run-rate synergies × realization fraction
A10: Less: dis-synergies | B10: =Assumptions!$B$37 -> 0.25 | C10: Stranded costs / content disruption
A11: Less: integration costs | B11: =Assumptions!$B$36 -> 1 | C11: One-time Year 1 integration costs
A12: Net pre-tax deal benefits | B12: =B9-B10-B11 -> -0.725 | C12: Synergies less dis-synergies and integration costs
A13: After-tax deal benefits | B13: =B12*(1-Assumptions!$B$17) -> -0.54375 | C13: Simplified tax treatment
A14: Acquisition debt | B14: =Transaction!D17 -> 9.0398 | C14: New debt funding
A15: After-tax incremental net interest expense | B15: =B29*(1-Assumptions!$B$17) -> 0.10477055 | C15: New-debt interest + foregone interest on buyer cash, less interest saved on refinanced target debt (see detail below), after tax
A16: New shares issued | B16: =Transaction!B25 -> 0.04 | C16: Stock consideration / share price
A17: Pro forma net income | B17: =B5+B8+B13-B15 -> -2.0485206 | C17: Buyer NI + target NI + after-tax benefits − after-tax interest
A18: Pro forma diluted shares | B18: =B6+B16 -> 0.74 | C18: Buyer shares plus new shares issued
A19: Pro forma EPS | B19: =B17/B18 -> -2.768271 | C19: Pro forma EPS
A20: EPS accretion / (dilution) % | B20: =IF(B7>0,B19/B7-1,"n.m.") -> n.m. | C20: n.m. (not meaningful) when standalone EPS is zero or negative; use the $ per share change below
A21: EPS change vs standalone ($ per share) | B21: =B19-B7 -> -2.1968424 | C21: Pro forma EPS less standalone EPS
A22: Pro forma EPS excl. one-time integration costs | B22: =(B17+B11*(1-Assumptions!$B$17))/B18 -> -1.7547575 | C22: Adds back after-tax one-time integration costs
A23: EPS change excl. one-time integration ($ per share) | B23: =B22-B7 -> -1.1833289 | C23: Run-rate view of Year 1
A25: INCREMENTAL INTEREST DETAIL (pre-tax, USD bn)
A26: Interest on new acquisition debt | B26: =B14*Assumptions!$B$22 -> 0.587587 | C26: New debt x pre-tax cost of debt
A27: Foregone interest on buyer cash used | B27: =Transaction!D19*Assumptions!$B$19 -> 0.2854404 | C27: Buyer cash / other funding x risk-free rate (proxy yield)
A28: Less: interest saved on refinanced target debt | B28: =-Assumptions!$B$28*(-Historical!D24/Historical!D28) -> -0.73333333 | C28: Refinanced debt x target 2025A implied rate (interest / net debt). Already inside target net income, so it must be removed.
A29: Net incremental pre-tax interest | B29: =SUM(B26:B28) -> 0.13969407
A31: Caution: EPS accretion is not the same as value creation. This simplified model omits purchase accounting, content amortization step-ups, financing fees, debt repayment schedules, tax attributes, integration timing and share price movements.

Sheet Sensitivity
A1: Sensitivity Analysis
A2: Illustrative scenarios. DCF EV varies with WACC/growth (normalized terminal FCFF); EPS change ($/share) varies with synergies/debt funding.
A4: DCF ENTERPRISE VALUE: WACC VS PERPETUAL GROWTH
A5: WACC \ Growth | B5: 0.01 | C5: 0.02 | D5: 0.025 | E5: 0.03 | F5: 0.035
A6: 0.075 | B6: =SUMPRODUCT(DCF!$B$11:$F$11,1/(1+$A6)^DCF!$B$12:$F$12)+(DCF!$B$43*(1+B$5)/($A6-B$5))/(1+$A6)^5 -> 86.141108 | C6: =SUMPRODUCT(DCF!$B$11:$F$11,1/(1+$A6)^DCF!$B$12:$F$12)+(DCF!$B$43*(1+C$5)/($A6-C$5))/(1+$A6)^5 -> 98.486243 | D6: =SUMPRODUCT(DCF!$B$11:$F$11,1/(1+$A6)^DCF!$B$12:$F$12)+(DCF!$B$43*(1+D$5)/($A6-D$5))/(1+$A6)^5 -> 106.51058 | E6: =SUMPRODUCT(DCF!$B$11:$F$11,1/(1+$A6)^DCF!$B$12:$F$12)+(DCF!$B$43*(1+E$5)/($A6-E$5))/(1+$A6)^5 -> 116.3181 | F6: =SUMPRODUCT(DCF!$B$11:$F$11,1/(1+$A6)^DCF!$B$12:$F$12)+(DCF!$B$43*(1+F$5)/($A6-F$5))/(1+$A6)^5 -> 128.57751
A7: 0.08 | B7: =SUMPRODUCT(DCF!$B$11:$F$11,1/(1+$A7)^DCF!$B$12:$F$12)+(DCF!$B$43*(1+B$5)/($A7-B$5))/(1+$A7)^5 -> 79.916672 | C7: =SUMPRODUCT(DCF!$B$11:$F$11,1/(1+$A7)^DCF!$B$12:$F$12)+(DCF!$B$43*(1+C$5)/($A7-C$5))/(1+$A7)^5 -> 90.231486 | D7: =SUMPRODUCT(DCF!$B$11:$F$11,1/(1+$A7)^DCF!$B$12:$F$12)+(DCF!$B$43*(1+D$5)/($A7-D$5))/(1+$A7)^5 -> 96.795459 | E7: =SUMPRODUCT(DCF!$B$11:$F$11,1/(1+$A7)^DCF!$B$12:$F$12)+(DCF!$B$43*(1+E$5)/($A7-E$5))/(1+$A7)^5 -> 104.67223 | F7: =SUMPRODUCT(DCF!$B$11:$F$11,1/(1+$A7)^DCF!$B$12:$F$12)+(DCF!$B$43*(1+F$5)/($A7-F$5))/(1+$A7)^5 -> 114.29939
A8: 0.085 | B8: =SUMPRODUCT(DCF!$B$11:$F$11,1/(1+$A8)^DCF!$B$12:$F$12)+(DCF!$B$43*(1+B$5)/($A8-B$5))/(1+$A8)^5 -> 74.522273 | C8: =SUMPRODUCT(DCF!$B$11:$F$11,1/(1+$A8)^DCF!$B$12:$F$12)+(DCF!$B$43*(1+C$5)/($A8-C$5))/(1+$A8)^5 -> 83.246203 | D8: =SUMPRODUCT(DCF!$B$11:$F$11,1/(1+$A8)^DCF!$B$12:$F$12)+(DCF!$B$43*(1+D$5)/($A8-D$5))/(1+$A8)^5 -> 88.698659 | E8: =SUMPRODUCT(DCF!$B$11:$F$11,1/(1+$A8)^DCF!$B$12:$F$12)+(DCF!$B$43*(1+E$5)/($A8-E$5))/(1+$A8)^5 -> 95.142471 | F8: =SUMPRODUCT(DCF!$B$11:$F$11,1/(1+$A8)^DCF!$B$12:$F$12)+(DCF!$B$43*(1+F$5)/($A8-F$5))/(1+$A8)^5 -> 102.87505
A9: 0.09 | B9: =SUMPRODUCT(DCF!$B$11:$F$11,1/(1+$A9)^DCF!$B$12:$F$12)+(DCF!$B$43*(1+B$5)/($A9-B$5))/(1+$A9)^5 -> 69.802303 | C9: =SUMPRODUCT(DCF!$B$11:$F$11,1/(1+$A9)^DCF!$B$12:$F$12)+(DCF!$B$43*(1+C$5)/($A9-C$5))/(1+$A9)^5 -> 77.258403 | D9: =SUMPRODUCT(DCF!$B$11:$F$11,1/(1+$A9)^DCF!$B$12:$F$12)+(DCF!$B$43*(1+D$5)/($A9-D$5))/(1+$A9)^5 -> 81.846772 | E9: =SUMPRODUCT(DCF!$B$11:$F$11,1/(1+$A9)^DCF!$B$12:$F$12)+(DCF!$B$43*(1+E$5)/($A9-E$5))/(1+$A9)^5 -> 87.19987 | F9: =SUMPRODUCT(DCF!$B$11:$F$11,1/(1+$A9)^DCF!$B$12:$F$12)+(DCF!$B$43*(1+F$5)/($A9-F$5))/(1+$A9)^5 -> 93.526257
A10: 0.095 | B10: =SUMPRODUCT(DCF!$B$11:$F$11,1/(1+$A10)^DCF!$B$12:$F$12)+(DCF!$B$43*(1+B$5)/($A10-B$5))/(1+$A10)^5 -> 65.637764 | C10: =SUMPRODUCT(DCF!$B$11:$F$11,1/(1+$A10)^DCF!$B$12:$F$12)+(DCF!$B$43*(1+C$5)/($A10-C$5))/(1+$A10)^5 -> 72.068624 | D10: =SUMPRODUCT(DCF!$B$11:$F$11,1/(1+$A10)^DCF!$B$12:$F$12)+(DCF!$B$43*(1+D$5)/($A10-D$5))/(1+$A10)^5 -> 75.973075 | E10: =SUMPRODUCT(DCF!$B$11:$F$11,1/(1+$A10)^DCF!$B$12:$F$12)+(DCF!$B$43*(1+E$5)/($A10-E$5))/(1+$A10)^5 -> 80.478211 | F10: =SUMPRODUCT(DCF!$B$11:$F$11,1/(1+$A10)^DCF!$B$12:$F$12)+(DCF!$B$43*(1+F$5)/($A10-F$5))/(1+$A10)^5 -> 85.734202
A14: EPS CHANGE ($ PER SHARE): SYNERGIES VS DEBT FUNDING
A15: Debt funding \ Synergies | B15: 0.75 | C15: 1 | D15: 1.5 | E15: 2 | F15: 2.5
A16: 0.35 | B16: =((Assumptions!$B$31+Assumptions!$B$33+(B$15*Assumptions!$B$35-Assumptions!$B$37-Assumptions!$B$36-(Transaction!$B$20*$A16*Assumptions!$B$22+(Transaction!$B$20-Transaction!$B$20*$A16-Transaction!$D$18)*Assumptions!$B$19-Assumptions!$B$28*(-Historical!$D$24/Historical!$D$28)))*(1-Assumptions!$B$17))/('Accretion-Dilution'!$B$6+Transaction!$B$25))-'Accretion-Dilution'!$B$7 -> -2.3862624 | C16: =((Assumptions!$B$31+Assumptions!$B$33+(C$15*Assumptions!$B$35-Assumptions!$B$37-Assumptions!$B$36-(Transaction!$B$20*$A16*Assumptions!$B$22+(Transaction!$B$20-Transaction!$B$20*$A16-Transaction!$D$18)*Assumptions!$B$19-Assumptions!$B$28*(-Historical!$D$24/Historical!$D$28)))*(1-Assumptions!$B$17))/('Accretion-Dilution'!$B$6+Transaction!$B$25))-'Accretion-Dilution'!$B$7 -> -2.29758 | D16: =((Assumptions!$B$31+Assumptions!$B$33+(D$15*Assumptions!$B$35-Assumptions!$B$37-Assumptions!$B$36-(Transaction!$B$20*$A16*Assumptions!$B$22+(Transaction!$B$20-Transaction!$B$20*$A16-Transaction!$D$18)*Assumptions!$B$19-Assumptions!$B$28*(-Historical!$D$24/Historical!$D$28)))*(1-Assumptions!$B$17))/('Accretion-Dilution'!$B$6+Transaction!$B$25))-'Accretion-Dilution'!$B$7 -> -2.1202151 | E16: =((Assumptions!$B$31+Assumptions!$B$33+(E$15*Assumptions!$B$35-Assumptions!$B$37-Assumptions!$B$36-(Transaction!$B$20*$A16*Assumptions!$B$22+(Transaction!$B$20-Transaction!$B$20*$A16-Transaction!$D$18)*Assumptions!$B$19-Assumptions!$B$28*(-Historical!$D$24/Historical!$D$28)))*(1-Assumptions!$B$17))/('Accretion-Dilution'!$B$6+Transaction!$B$25))-'Accretion-Dilution'!$B$7 -> -1.9428503 | F16: =((Assumptions!$B$31+Assumptions!$B$33+(F$15*Assumptions!$B$35-Assumptions!$B$37-Assumptions!$B$36-(Transaction!$B$20*$A16*Assumptions!$B$22+(Transaction!$B$20-Transaction!$B$20*$A16-Transaction!$D$18)*Assumptions!$B$19-Assumptions!$B$28*(-Historical!$D$24/Historical!$D$28)))*(1-Assumptions!$B$17))/('Accretion-Dilution'!$B$6+Transaction!$B$25))-'Accretion-Dilution'!$B$7 -> -1.7654854
A17: 0.45 | B17: =((Assumptions!$B$31+Assumptions!$B$33+(B$15*Assumptions!$B$35-Assumptions!$B$37-Assumptions!$B$36-(Transaction!$B$20*$A17*Assumptions!$B$22+(Transaction!$B$20-Transaction!$B$20*$A17-Transaction!$D$18)*Assumptions!$B$19-Assumptions!$B$28*(-Historical!$D$24/Historical!$D$28)))*(1-Assumptions!$B$17))/('Accretion-Dilution'!$B$6+Transaction!$B$25))-'Accretion-Dilution'!$B$7 -> -2.4245761 | C17: =((Assumptions!$B$31+Assumptions!$B$33+(C$15*Assumptions!$B$35-Assumptions!$B$37-Assumptions!$B$36-(Transaction!$B$20*$A17*Assumptions!$B$22+(Transaction!$B$20-Transaction!$B$20*$A17-Transaction!$D$18)*Assumptions!$B$19-Assumptions!$B$28*(-Historical!$D$24/Historical!$D$28)))*(1-Assumptions!$B$17))/('Accretion-Dilution'!$B$6+Transaction!$B$25))-'Accretion-Dilution'!$B$7 -> -2.3358937 | D17: =((Assumptions!$B$31+Assumptions!$B$33+(D$15*Assumptions!$B$35-Assumptions!$B$37-Assumptions!$B$36-(Transaction!$B$20*$A17*Assumptions!$B$22+(Transaction!$B$20-Transaction!$B$20*$A17-Transaction!$D$18)*Assumptions!$B$19-Assumptions!$B$28*(-Historical!$D$24/Historical!$D$28)))*(1-Assumptions!$B$17))/('Accretion-Dilution'!$B$6+Transaction!$B$25))-'Accretion-Dilution'!$B$7 -> -2.1585288 | E17: =((Assumptions!$B$31+Assumptions!$B$33+(E$15*Assumptions!$B$35-Assumptions!$B$37-Assumptions!$B$36-(Transaction!$B$20*$A17*Assumptions!$B$22+(Transaction!$B$20-Transaction!$B$20*$A17-Transaction!$D$18)*Assumptions!$B$19-Assumptions!$B$28*(-Historical!$D$24/Historical!$D$28)))*(1-Assumptions!$B$17))/('Accretion-Dilution'!$B$6+Transaction!$B$25))-'Accretion-Dilution'!$B$7 -> -1.9811639 | F17: =((Assumptions!$B$31+Assumptions!$B$33+(F$15*Assumptions!$B$35-Assumptions!$B$37-Assumptions!$B$36-(Transaction!$B$20*$A17*Assumptions!$B$22+(Transaction!$B$20-Transaction!$B$20*$A17-Transaction!$D$18)*Assumptions!$B$19-Assumptions!$B$28*(-Historical!$D$24/Historical!$D$28)))*(1-Assumptions!$B$17))/('Accretion-Dilution'!$B$6+Transaction!$B$25))-'Accretion-Dilution'!$B$7 -> -1.8037991
A18: 0.55 | B18: =((Assumptions!$B$31+Assumptions!$B$33+(B$15*Assumptions!$B$35-Assumptions!$B$37-Assumptions!$B$36-(Transaction!$B$20*$A18*Assumptions!$B$22+(Transaction!$B$20-Transaction!$B$20*$A18-Transaction!$D$18)*Assumptions!$B$19-Assumptions!$B$28*(-Historical!$D$24/Historical!$D$28)))*(1-Assumptions!$B$17))/('Accretion-Dilution'!$B$6+Transaction!$B$25))-'Accretion-Dilution'!$B$7 -> -2.4628897 | C18: =((Assumptions!$B$31+Assumptions!$B$33+(C$15*Assumptions!$B$35-Assumptions!$B$37-Assumptions!$B$36-(Transaction!$B$20*$A18*Assumptions!$B$22+(Transaction!$B$20-Transaction!$B$20*$A18-Transaction!$D$18)*Assumptions!$B$19-Assumptions!$B$28*(-Historical!$D$24/Historical!$D$28)))*(1-Assumptions!$B$17))/('Accretion-Dilution'!$B$6+Transaction!$B$25))-'Accretion-Dilution'!$B$7 -> -2.3742073 | D18: =((Assumptions!$B$31+Assumptions!$B$33+(D$15*Assumptions!$B$35-Assumptions!$B$37-Assumptions!$B$36-(Transaction!$B$20*$A18*Assumptions!$B$22+(Transaction!$B$20-Transaction!$B$20*$A18-Transaction!$D$18)*Assumptions!$B$19-Assumptions!$B$28*(-Historical!$D$24/Historical!$D$28)))*(1-Assumptions!$B$17))/('Accretion-Dilution'!$B$6+Transaction!$B$25))-'Accretion-Dilution'!$B$7 -> -2.1968424 | E18: =((Assumptions!$B$31+Assumptions!$B$33+(E$15*Assumptions!$B$35-Assumptions!$B$37-Assumptions!$B$36-(Transaction!$B$20*$A18*Assumptions!$B$22+(Transaction!$B$20-Transaction!$B$20*$A18-Transaction!$D$18)*Assumptions!$B$19-Assumptions!$B$28*(-Historical!$D$24/Historical!$D$28)))*(1-Assumptions!$B$17))/('Accretion-Dilution'!$B$6+Transaction!$B$25))-'Accretion-Dilution'!$B$7 -> -2.0194776 | F18: =((Assumptions!$B$31+Assumptions!$B$33+(F$15*Assumptions!$B$35-Assumptions!$B$37-Assumptions!$B$36-(Transaction!$B$20*$A18*Assumptions!$B$22+(Transaction!$B$20-Transaction!$B$20*$A18-Transaction!$D$18)*Assumptions!$B$19-Assumptions!$B$28*(-Historical!$D$24/Historical!$D$28)))*(1-Assumptions!$B$17))/('Accretion-Dilution'!$B$6+Transaction!$B$25))-'Accretion-Dilution'!$B$7 -> -1.8421127
A19: 0.65 | B19: =((Assumptions!$B$31+Assumptions!$B$33+(B$15*Assumptions!$B$35-Assumptions!$B$37-Assumptions!$B$36-(Transaction!$B$20*$A19*Assumptions!$B$22+(Transaction!$B$20-Transaction!$B$20*$A19-Transaction!$D$18)*Assumptions!$B$19-Assumptions!$B$28*(-Historical!$D$24/Historical!$D$28)))*(1-Assumptions!$B$17))/('Accretion-Dilution'!$B$6+Transaction!$B$25))-'Accretion-Dilution'!$B$7 -> -2.5012034 | C19: =((Assumptions!$B$31+Assumptions!$B$33+(C$15*Assumptions!$B$35-Assumptions!$B$37-Assumptions!$B$36-(Transaction!$B$20*$A19*Assumptions!$B$22+(Transaction!$B$20-Transaction!$B$20*$A19-Transaction!$D$18)*Assumptions!$B$19-Assumptions!$B$28*(-Historical!$D$24/Historical!$D$28)))*(1-Assumptions!$B$17))/('Accretion-Dilution'!$B$6+Transaction!$B$25))-'Accretion-Dilution'!$B$7 -> -2.412521 | D19: =((Assumptions!$B$31+Assumptions!$B$33+(D$15*Assumptions!$B$35-Assumptions!$B$37-Assumptions!$B$36-(Transaction!$B$20*$A19*Assumptions!$B$22+(Transaction!$B$20-Transaction!$B$20*$A19-Transaction!$D$18)*Assumptions!$B$19-Assumptions!$B$28*(-Historical!$D$24/Historical!$D$28)))*(1-Assumptions!$B$17))/('Accretion-Dilution'!$B$6+Transaction!$B$25))-'Accretion-Dilution'!$B$7 -> -2.2351561 | E19: =((Assumptions!$B$31+Assumptions!$B$33+(E$15*Assumptions!$B$35-Assumptions!$B$37-Assumptions!$B$36-(Transaction!$B$20*$A19*Assumptions!$B$22+(Transaction!$B$20-Transaction!$B$20*$A19-Transaction!$D$18)*Assumptions!$B$19-Assumptions!$B$28*(-Historical!$D$24/Historical!$D$28)))*(1-Assumptions!$B$17))/('Accretion-Dilution'!$B$6+Transaction!$B$25))-'Accretion-Dilution'!$B$7 -> -2.0577912 | F19: =((Assumptions!$B$31+Assumptions!$B$33+(F$15*Assumptions!$B$35-Assumptions!$B$37-Assumptions!$B$36-(Transaction!$B$20*$A19*Assumptions!$B$22+(Transaction!$B$20-Transaction!$B$20*$A19-Transaction!$D$18)*Assumptions!$B$19-Assumptions!$B$28*(-Historical!$D$24/Historical!$D$28)))*(1-Assumptions!$B$17))/('Accretion-Dilution'!$B$6+Transaction!$B$25))-'Accretion-Dilution'!$B$7 -> -1.8804264
A20: 0.75 | B20: =((Assumptions!$B$31+Assumptions!$B$33+(B$15*Assumptions!$B$35-Assumptions!$B$37-Assumptions!$B$36-(Transaction!$B$20*$A20*Assumptions!$B$22+(Transaction!$B$20-Transaction!$B$20*$A20-Transaction!$D$18)*Assumptions!$B$19-Assumptions!$B$28*(-Historical!$D$24/Historical!$D$28)))*(1-Assumptions!$B$17))/('Accretion-Dilution'!$B$6+Transaction!$B$25))-'Accretion-Dilution'!$B$7 -> -2.539517 | C20: =((Assumptions!$B$31+Assumptions!$B$33+(C$15*Assumptions!$B$35-Assumptions!$B$37-Assumptions!$B$36-(Transaction!$B$20*$A20*Assumptions!$B$22+(Transaction!$B$20-Transaction!$B$20*$A20-Transaction!$D$18)*Assumptions!$B$19-Assumptions!$B$28*(-Historical!$D$24/Historical!$D$28)))*(1-Assumptions!$B$17))/('Accretion-Dilution'!$B$6+Transaction!$B$25))-'Accretion-Dilution'!$B$7 -> -2.4508346 | D20: =((Assumptions!$B$31+Assumptions!$B$33+(D$15*Assumptions!$B$35-Assumptions!$B$37-Assumptions!$B$36-(Transaction!$B$20*$A20*Assumptions!$B$22+(Transaction!$B$20-Transaction!$B$20*$A20-Transaction!$D$18)*Assumptions!$B$19-Assumptions!$B$28*(-Historical!$D$24/Historical!$D$28)))*(1-Assumptions!$B$17))/('Accretion-Dilution'!$B$6+Transaction!$B$25))-'Accretion-Dilution'!$B$7 -> -2.2734697 | E20: =((Assumptions!$B$31+Assumptions!$B$33+(E$15*Assumptions!$B$35-Assumptions!$B$37-Assumptions!$B$36-(Transaction!$B$20*$A20*Assumptions!$B$22+(Transaction!$B$20-Transaction!$B$20*$A20-Transaction!$D$18)*Assumptions!$B$19-Assumptions!$B$28*(-Historical!$D$24/Historical!$D$28)))*(1-Assumptions!$B$17))/('Accretion-Dilution'!$B$6+Transaction!$B$25))-'Accretion-Dilution'!$B$7 -> -2.0961049 | F20: =((Assumptions!$B$31+Assumptions!$B$33+(F$15*Assumptions!$B$35-Assumptions!$B$37-Assumptions!$B$36-(Transaction!$B$20*$A20*Assumptions!$B$22+(Transaction!$B$20-Transaction!$B$20*$A20-Transaction!$D$18)*Assumptions!$B$19-Assumptions!$B$28*(-Historical!$D$24/Historical!$D$28)))*(1-Assumptions!$B$17))/('Accretion-Dilution'!$B$6+Transaction!$B$25))-'Accretion-Dilution'!$B$7 -> -1.91874
A23: Interpretation: lower WACC and higher terminal growth raise DCF value; higher synergies may improve EPS, while debt financing raises interest expense and leverage risk. Never assume full synergy capture without an integration plan. EPS grid is $ per share because standalone EPS is negative on 2025A inputs.

Sheet Change Log
A1: Change Log: review of the model
A2: USD billions. "Before" values are from the original file (hard-coded for reference); "After" values are live formulas.
A4: # | B4: Issue | C4: Where | D4: Fix applied
A5: 1 | B5: Net debt in equity bridge subtracted the refinanced $14bn, giving $43bn instead of $57bn | C5: DCF!B33 | D5: Now = Historical net debt (acquirer + target), $57bn
A6: 2 | B6: Terminal year left D&A (7% of revenue) above capex (4%) forever, overstating the terminal tax shield | C6: DCF rows 38-43; Assumptions!B40 | D6: Terminal D&A normalized to capex; terminal FCFF rebuilt (EBIT, tax, NOPAT). Sensitivity grid re-pointed to the normalized figure.
A7: 3 | B7: EBITDA margin jumped from 12.3% (2025A) to 16% in 2026 and 20% by 2030 while history was declining | C7: Assumptions!B10:B14 | D7: Path reset to 12.5% rising 0.5pt/yr to 14.5%. Judgment call: change it if you have a sourced view.
A8: 4 | B8: DCF was ~2x the comps cross-check with no reconciliation | C8: DCF rows 45-52 | D8: Added DCF vs comps premium, implied EV/EBITDA, implied terminal multiple, TV share.
A9: 5 | B9: $28bn of target debt disappeared: only $14bn refinanced and $0 retained against $42bn net debt | C9: Assumptions!B29; Transaction!B26 | D9: Retained debt = target net debt less refinanced. Added a check cell (should be 0).
A10: 6 | B10: Target equity ($2bn) is a thin residual of EV less net debt, extremely sensitive to the multiple | C10: Comps rows 24-31 | D10: Added sensitivity showing equity at +/-1.0x (negative at 7.0x). Offer price still illustrative.
A11: 7 | B11: EPS inputs ($1.2bn / $0.45bn) contradicted the Historical sheet (2025A: -$0.4bn / -$1.0bn) | C11: Assumptions!B31, B33 | D11: Linked to Historical 2025A. % accretion shows n.m. when standalone EPS <= 0; $ per share change added.
A12: 8 | B12: Interest was double counted: new debt interest added on top of the existing interest on the $14bn it refinances; foregone interest on buyer cash was ignored | C12: Accretion-Dilution rows 15, 25-29; Sensitivity grid | D12: Net incremental interest = new debt + foregone cash interest - interest saved on refinanced debt.
A13: 9 | B13: Year 1 EPS was burdened by the one-time $1bn integration cost with no run-rate view | C13: Accretion-Dilution rows 22-23 | D13: Added EPS excluding one-time integration costs.
A14: 10 | B14: Model vs real deal not reconciled | C14: Public Deal Facts rows 15-17 | D14: Added model vs reported equity value, EV and net debt.
B16: Key output | C16: Before (original) | D16: After (corrected)
B17: DCF enterprise value | C17: 126.442 | D17: =DCF!B32 -> 80.447803
B18: Net debt used in equity bridge | C18: 43 | D18: =DCF!B33 -> 57
B19: DCF equity value | C19: 83.442 | D19: =DCF!B34 -> 23.447803
B20: DCF EV / 2025A EBITDA | C20: 15.610123 | D20: =DCF!B49 -> 9.9318275
B21: DCF premium to comps EV | C21: 0.95126543 | D21: =DCF!B48 -> 0.24147844
B22: Implied transaction EV | C22: 16.4 | D22: =Transaction!B12 -> 44.4
B23: EPS accretion / (dilution) % | C23: -0.47535 | D23: ='Accretion-Dilution'!B20 -> n.m.
B24: EPS change ($ per share) | C24: -0.81488 | D24: ='Accretion-Dilution'!B21 -> -2.1968424
B25: EPS change excl. one-time integration ($ per share) | C25: n/a | D25: ='Accretion-Dilution'!B23 -> -1.1833289
B27: Open items (not changed)
B28: Revenue growth of +2-3% still contrasts with declining 2023-2025 revenue; consider flat-to-declining years first.
B29: Content cash spend is not modelled separately from capex; if "D&A" includes content amortization, FCFF may be overstated.
B30: WACC inputs (beta, ERP, risk-free, capital structure) are illustrative placeholders, not sourced market data.
B31: DCF excludes synergies and integration costs; they are shown only in the synergy bridge and EPS analysis.
B32: End-of-year discounting is used; mid-year convention would raise value by roughly 4-5%.
B33: Fictional peer set and 8.0x multiple are not market data.
